Workbook

Sheet Línea a línea
A1: Factura | B1: Nº | C1: Material / concepto | D1: Importe TTI | E1: Destino | F1: % Rep. | G1: % Mej. | H1: % Fuera | I1: Imp. reparación | J1: Imp. mejora | K1: Imp. fuera | L1: Motivo | M1: Confianza
A2: 399514 (228131) · 28/11/2023 | B2: 1 | C2: Montante EGA 46mm | D2: 58.11 | E2: Mejora | F2: 0 | G2: 1 | H2: 0 | I2: =D2*F2 -> 0 | J2: =D2*G2 -> 58.11 | K2: =D2*H2 -> 0 | L2: Tabiquería de pladur (división de baño + habitación nueva) — redistribución, art. 14 | M2: Alta
B3: 2 | C3: Yeso controlado YESODUR | D3: 15.2 | E3: Mixto 50/50 | F3: 0.5 | G3: 0.5 | H3: 0 | I3: =D3*F3 -> 7.6 | J3: =D3*G3 -> 7.6 | K3: =D3*H3 -> 0 | L3: Material general (yeso/cemento/mortero/plaste); alisado (rep.) + obra nueva (mej.) — 50/50 | M3: Media
B4: 3 | C4: Cinta red autoadhesiva | D4: 7 | E4: Mejora | F4: 0 | G4: 1 | H4: 0 | I4: =D4*F4 -> 0 | J4: =D4*G4 -> 7 | K4: =D4*H4 -> 0 | L4: Tabiquería de pladur (división de baño + habitación nueva) — redistribución, art. 14 | M4: Alta
B5: 4 | C5: Cinta juntas | D5: 3.6 | E5: Mejora | F5: 0 | G5: 1 | H5: 0 | I5: =D5*F5 -> 0 | J5: =D5*G5 -> 3.6 | K5: =D5*H5 -> 0 | L5: Tabiquería de pladur (división de baño + habitación nueva) — redistribución, art. 14 | M5: Alta
B6: 5 | C6: Placa yeso acústica PPH 13mm | D6: 339.66 | E6: Mejora | F6: 0 | G6: 1 | H6: 0 | I6: =D6*F6 -> 0 | J6: =D6*G6 -> 339.66 | K6: =D6*H6 -> 0 | L6: Tabiquería de pladur (división de baño + habitación nueva) — redistribución, art. 14 | M6: Alta
B7: 6 | C7: Rollo esparto mezcla | D7: 4.95 | E7: Mixto 50/50 | F7: 0.5 | G7: 0.5 | H7: 0 | I7: =D7*F7 -> 2.475 | J7: =D7*G7 -> 2.475 | K7: =D7*H7 -> 0 | L7: Material general (yeso/cemento/mortero/plaste); alisado (rep.) + obra nueva (mej.) — 50/50 | M7: Media
B8: 7 | C8: Pasta juntas Plakist | D8: 23 | E8: Mejora | F8: 0 | G8: 1 | H8: 0 | I8: =D8*F8 -> 0 | J8: =D8*G8 -> 23 | K8: =D8*H8 -> 0 | L8: Tabiquería de pladur (división de baño + habitación nueva) — redistribución, art. 14 | M8: Alta
B9: 8 | C9: Lad 12 huecos tabicón | D9: 3.48 | E9: Mejora | F9: 0 | G9: 1 | H9: 0 | I9: =D9*F9 -> 0 | J9: =D9*G9 -> 3.48 | K9: =D9*H9 -> 0 | L9: Tabiquería de pladur (división de baño + habitación nueva) — redistribución, art. 14 | M9: Alta
B10: 9 | C10: Escayola Indayola | D10: 5.8 | E10: Mixto 50/50 | F10: 0.5 | G10: 0.5 | H10: 0 | I10: =D10*F10 -> 2.9 | J10: =D10*G10 -> 2.9 | K10: =D10*H10 -> 0 | L10: Material general (yeso/cemento/mortero/plaste); alisado (rep.) + obra nueva (mej.) — 50/50 | M10: Media
B11: 10 | C11: 500 torn THTPF | D11: 32.3 | E11: Mejora | F11: 0 | G11: 1 | H11: 0 | I11: =D11*F11 -> 0 | J11: =D11*G11 -> 32.3 | K11: =D11*H11 -> 0 | L11: Tabiquería de pladur (división de baño + habitación nueva) — redistribución, art. 14 | M11: Alta
B12: 11 | C12: Canal EGA 46mm | D12: 69.53 | E12: Mejora | F12: 0 | G12: 1 | H12: 0 | I12: =D12*F12 -> 0 | J12: =D12*G12 -> 69.53 | K12: =D12*H12 -> 0 | L12: Tabiquería de pladur (división de baño + habitación nueva) — redistribución, art. 14 | M12: Alta
B13: 12 | C13: Mort autonivelante Aplicalevel | D13: 22.2 | E13: Mejora | F13: 0 | G13: 1 | H13: 0 | I13: =D13*F13 -> 0 | J13: =D13*G13 -> 22.2 | K13: =D13*H13 -> 0 | L13: Suelo laminado nuevo y su base — art. 14 | M13: Alta
B14: 13 | C14: Lad hueco tabiquero | D14: 2.5 | E14: Mejora | F14: 0 | G14: 1 | H14: 0 | I14: =D14*F14 -> 0 | J14: =D14*G14 -> 2.5 | K14: =D14*H14 -> 0 | L14: Tabiquería de pladur (división de baño + habitación nueva) — redistribución, art. 14 | M14: Alta
... B95: 94 | C95: Preparación mercancía | D95: 8.76 | E95: Logística (prorr.) | F95: 0.179 | G95: 0.821 | H95: 0 | I95: =D95*F95 -> 1.56804 | J95: =D95*G95 -> 7.19196 | K95: =D95*H95 -> 0 | L95: Coste logístico — prorrateado según el peso reparación/mejora de la factura | M95: Alta
A96: 404381 (228543) · 07/12/2023 | B96: 1 | C96: Lad 8 huecos tabicón | D96: 8.6 | E96: Mejora | F96: 0 | G96: 1 | H96: 0 | I96: =D96*F96 -> 0 | J96: =D96*G96 -> 8.6 | K96: =D96*H96 -> 0 | L96: Tabiquería de pladur (división de baño + habitación nueva) — redistribución, art. 14 | M96: Alta
B97: 2 | C97: Escayola Aislayola | D97: 36.5 | E97: Mixto 50/50 | F97: 0.5 | G97: 0.5 | H97: 0 | I97: =D97*F97 -> 18.25 | J97: =D97*G97 -> 18.25 | K97: =D97*H97 -> 0 | L97: Material general (yeso/cemento/mortero/plaste); alisado (rep.) + obra nueva (mej.) — 50/50 | M97: Media
B98: 3 | C98: Caja empo 3 mec tab hueco | D98: 4.46 | E98: Mejora | F98: 0 | G98: 1 | H98: 0 | I98: =D98*F98 -> 0 | J98: =D98*G98 -> 4.46 | K98: =D98*H98 -> 0 | L98: Tabiquería de pladur (división de baño + habitación nueva) — redistribución, art. 14 | M98: Alta
B99: 4 | C99: Caja empo 2 mec tab hueco | D99: 5.36 | E99: Mejora | F99: 0 | G99: 1 | H99: 0 | I99: =D99*F99 -> 0 | J99: =D99*G99 -> 5.36 | K99: =D99*H99 -> 0 | L99: Tabiquería de pladur (división de baño + habitación nueva) — redistribución, art. 14 | M99: Alta
B100: 5 | C100: Tubo corrugado 25mm 75m | D100: 13.42 | E100: Mixto 50/50 | F100: 0.5 | G100: 0.5 | H100: 0 | I100: =D100*F100 -> 6.71 | J100: =D100*G100 -> 6.71 | K100: =D100*H100 -> 0 | L100: Fontanería/saneamiento; baño existente (rep.) + segundo baño (mej.) — 50/50 | M100: Media
B101: 6 | C101: Tubo corrugado 20mm 100m | D101: 13.85 | E101: Mixto 50/50 | F101: 0.5 | G101: 0.5 | H101: 0 | I101: =D101*F101 -> 6.925 | J101: =D101*G101 -> 6.925 | K101: =D101*H101 -> 0 | L101: Fontanería/saneamiento; baño existente (rep.) + segundo baño (mej.) — 50/50 | M101: Media
B102: 7 | C102: Caja empo tapa garra | D102: 3.28 | E102: Mixto 50/50 | F102: 0.5 | G102: 0.5 | H102: 0 | I102: =D102*F102 -> 1.64 | J102: =D102*G102 -> 1.64 | K102: =D102*H102 -> 0 | L102: Material general (yeso/cemento/mortero/plaste); alisado (rep.) + obra nueva (mej.) — 50/50 | M102: Media
B103: 8 | C103: Caja empo mec enlazable | D103: 1.2 | E103: Mixto 50/50 | F103: 0.5 | G103: 0.5 | H103: 0 | I103: =D103*F103 -> 0.6 | J103: =D103*G103 -> 0.6 | K103: =D103*H103 -> 0 | L103: Material general (yeso/cemento/mortero/plaste); alisado (rep.) + obra nueva (mej.) — 50/50 | M103: Media
B104: 9 | C104: Caja empo 1 mec tab hueco | D104: 1.38 | E104: Mejora | F104: 0 | G104: 1 | H104: 0 | I104: =D104*F104 -> 0 | J104: =D104*G104 -> 1.38 | K104: =D104*H104 -> 0 | L104: Tabiquería de pladur (división de baño + habitación nueva) — redistribución, art. 14 | M104: Alta
B105: 10 | C105: Caja empo tab hueco tapa torn | D105: 6.78 | E105: Mejora | F105: 0 | G105: 1 | H105: 0 | I105: =D105*F105 -> 0 | J105: =D105*G105 -> 6.78 | K105: =D105*H105 -> 0 | L105: Tabiquería de pladur (división de baño + habitación nueva) — redistribución, art. 14 | M105: Alta
B106: 11 | C106: Te 18mm cobre | D106: 7.4 | E106: Mixto 50/50 | F106: 0.5 | G106: 0.5 | H106: 0 | I106: =D106*F106 -> 3.7 | J106: =D106*G106 -> 3.7 | K106: =D106*H106 -> 0 | L106: Fontanería/saneamiento; baño existente (rep.) + segundo baño (mej.) — 50/50 | M106: Media
B107: 12 | C107: Manguito 18mm cobre | D107: 1.2 | E107: Mixto 50/50 | F107: 0.5 | G107: 0.5 | H107: 0 | I107: =D107*F107 -> 0.6 | J107: =D107*G107 -> 0.6 | K107: =D107*H107 -> 0 | L107: Fontanería/saneamiento; baño existente (rep.) + segundo baño (mej.) — 50/50 | M107: Media
B108: 13 | C108: Barra 18mm cobre (2u) | D108: 28.3 | E108: Mixto 50/50 | F108: 0.5 | G108: 0.5 | H108: 0 | I108: =D108*F108 -> 14.15 | J108: =D108*G108 -> 14.15 | K108: =D108*H108 -> 0 | L108: Fontanería/saneamiento; baño existente (rep.) + segundo baño (mej.) — 50/50 | M108: Media
... B112: 17 | C112: Preparación mercancía | D112: 9 | E112: Logística (prorr.) | F112: 0.4126 | G112: 0.5874 | H112: 0 | I112: =D112*F112 -> 3.7134 | J112: =D112*G112 -> 5.2866 | K112: =D112*H112 -> 0 | L112: Coste logístico — prorrateado según el peso reparación/mejora de la factura | M112: Alta
A113: 424413 (229407) · 17/01/2024 | B113: 1 | C113: Yeso controlado | D113: 7.6 | E113: Mixto 50/50 | F113: 0.5 | G113: 0.5 | H113: 0 | I113: =D113*F113 -> 3.8 | J113: =D113*G113 -> 3.8 | K113: =D113*H113 -> 0 | L113: Material general (yeso/cemento/mortero/plaste); alisado (rep.) + obra nueva (mej.) — 50/50 | M113: Media
B114: 2 | C114: Placa yeso acústica | D114: 55.29 | E114: Mejora | F114: 0 | G114: 1 | H114: 0 | I114: =D114*F114 -> 0 | J114: =D114*G114 -> 55.29 | K114: =D114*H114 -> 0 | L114: Tabiquería de pladur (división de baño + habitación nueva) — redistribución, art. 14 | M114: Alta
B115: 3 | C115: Lad 12 huecos tabicón | D115: 12.18 | E115: Mejora | F115: 0 | G115: 1 | H115: 0 | I115: =D115*F115 -> 0 | J115: =D115*G115 -> 12.18 | K115: =D115*H115 -> 0 | L115: Tabiquería de pladur (división de baño + habitación nueva) — redistribución, art. 14 | M115: Alta
B116: 4 | C116: Cemento S/M | D116: 10.5 | E116: Mixto 50/50 | F116: 0.5 | G116: 0.5 | H116: 0 | I116: =D116*F116 -> 5.25 | J116: =D116*G116 -> 5.25 | K116: =D116*H116 -> 0 | L116: Material general (yeso/cemento/mortero/plaste); alisado (rep.) + obra nueva (mej.) — 50/50 | M116: Media
B117: 5 | C117: 1000 torn tipo PM | D117: 6.3 | E117: Mejora | F117: 0 | G117: 1 | H117: 0 | I117: =D117*F117 -> 0 | J117: =D117*G117 -> 6.3 | K117: =D117*H117 -> 0 | L117: Tabiquería de pladur (división de baño + habitación nueva) — redistribución, art. 14 | M117: Alta
B118: 6 | C118: Kit 5 molduras ala | D118: 39.06 | E118: Mejora | F118: 0 | G118: 1 | H118: 0 | I118: =D118*F118 -> 0 | J118: =D118*G118 -> 39.06 | K118: =D118*H118 -> 0 | L118: Carpintería nueva (puertas/ventana) de la redistribución — art. 14 (prudente) | M118: Media-alta
B119: 7 | C119: Bolsa 100 cuñas madera | D119: 5.9 | E119: Mixto 50/50 | F119: 0.5 | G119: 0.5 | H119: 0 | I119: =D119*F119 -> 2.95 | J119: =D119*G119 -> 2.95 | K119: =D119*H119 -> 0 | L119: Material general (yeso/cemento/mortero/plaste); alisado (rep.) + obra nueva (mej.) — 50/50 | M119: Media
B120: 8 | C120: Pta block VT5 62.5 izq | D120: 119 | E120: Mejora | F120: 0 | G120: 1 | H120: 0 | I120: =D120*F120 -> 0 | J120: =D120*G120 -> 119 | K120: =D120*H120 -> 0 | L120: Carpintería nueva (puertas/ventana) de la redistribución — art. 14 (prudente) | M120: Media-alta
B121: 9 | C121: Azulejo 25x50 Elia Pearl | D121: 221.8 | E121: Mixto 50/50 | F121: 0.5 | G121: 0.5 | H121: 0 | I121: =D121*F121 -> 110.9 | J121: =D121*G121 -> 110.9 | K121: =D121*H121 -> 0 | L121: Alicatado/cerámico; baño existente (rep.) + segundo baño (mej.) — 50/50 | M121: Media
B122: 10 | C122: Azulejo 25x50 Elia decor | D122: 91.16 | E122: Mixto 50/50 | F122: 0.5 | G122: 0.5 | H122: 0 | I122: =D122*F122 -> 45.58 | J122: =D122*G122 -> 45.58 | K122: =D122*H122 -> 0 | L122: Alicatado/cerámico; baño existente (rep.) + segundo baño (mej.) — 50/50 | M122: Media
B123: 11 | C123: Plato ducha resina 70x90 | D123: 96.03 | E123: Mixto 50/50 | F123: 0.5 | G123: 0.5 | H123: 0 | I123: =D123*F123 -> 48.015 | J123: =D123*G123 -> 48.015 | K123: =D123*H123 -> 0 | L123: Sanitario/grifería; 2 uds sin identificar baño existente vs. nuevo — 50/50 | M123: Media
...

Sheet Resumen por factura
A1: Factura | B1: Total TTI | C1: Reparación | D1: Mejora | E1: Fuera | F1: % Rep. | G1: % Mej.
A2: 399514 (228131) · 28/11/2023 | B2: =SUM('Línea a línea'!D2:D95) -> 4803.37 | C2: =SUM('Línea a línea'!I2:I95) -> 859.89804 | D2: =SUM('Línea a línea'!J2:J95) -> 3943.472 | E2: =SUM('Línea a línea'!K2:K95) -> 0 | F2: =C2/(C2+D2) -> 0.17901974 | G2: =D2/(C2+D2) -> 0.82098026
A3: 404381 (228543) · 07/12/2023 | B3: =SUM('Línea a línea'!D96:D112) -> 161.13 | C3: =SUM('Línea a línea'!I96:I112) -> 66.4884 | D3: =SUM('Línea a línea'!J96:J112) -> 94.6416 | E3: =SUM('Línea a línea'!K96:K112) -> 0 | F3: =C3/(C3+D3) -> 0.41263824 | G3: =D3/(C3+D3) -> 0.58736176
A4: 424413 (229407) · 17/01/2024 | B4: =SUM('Línea a línea'!D113:D133) -> 1037.22 | C4: =SUM('Línea a línea'!I113:I133) -> 323.5524 | D4: =SUM('Línea a línea'!J113:J133) -> 604.6676 | E4: =SUM('Línea a línea'!K113:K133) -> 109 | F4: =C4/(C4+D4) -> 0.34857297 | G4: =D4/(C4+D4) -> 0.65142703
A5: 437264 (230379) · 08/02/2024 | B5: =SUM('Línea a línea'!D134:D141) -> 150.37 | C5: =SUM('Línea a línea'!I134:I141) -> 75.185 | D5: =SUM('Línea a línea'!J134:J141) -> 75.185 | E5: =SUM('Línea a línea'!K134:K141) -> 0 | F5: =C5/(C5+D5) -> 0.5 | G5: =D5/(C5+D5) -> 0.5
A6: TOTAL OBRAMAT | B6: =SUM(B2:B5) -> 6152.09 | C6: =SUM(C2:C5) -> 1325.1238 | D6: =SUM(D2:D5) -> 4717.9662 | E6: =SUM(E2:E5) -> 109 | F6: =C6/(C6+D6) -> 0.21927918 | G6: =D6/(C6+D6) -> 0.78072082

Sheet Conciliación global
A1: Bloque | B1: Importe (€) | C1: Reparación | D1: Mejora | E1: Fuera/no incl. | F1: Tratamiento
A2: Factura SB 014/2024 (mano de obra) | B2: 16335 | C2: 6900 | D2: 9435 | E2: 0 | F2: Reparto certificado (no se modifica)
A3: OBRAMAT — 4 facturas (línea a línea) | B3: ='Resumen por factura'!B6 -> 6152.09 | C3: ='Resumen por factura'!C6 -> 1325.1238 | D3: ='Resumen por factura'!D6 -> 4717.9662 | E3: ='Resumen por factura'!E6 -> 109 | F3: Clasificación línea a línea
A4: TOTAL POOL REFORMA | B4: =B2+B3 -> 22487.09 | C4: =C2+C3 -> 8225.1238 | D4: =D2+D3 -> 14152.966 | E4: =E2+E3 -> 109 | F4: Rep. deducible / Mej. amortizable 3%
A5: Mobiliario y equipamiento | B5: 1736.12 | C5: 0 | D5: 0 | E5: 0 | F5: Amortizable 10% (bloque separado)
A6: TOTAL GLOBAL DOCUMENTADO | B6: =B4+B5 -> 24223.21
A9: Nota: el termo (109,00 €) está en la factura 424413 pero se excluye por decisión del contribuyente (columna Fuera). Los 4 satélites no aportados (404213, 407792, 452497, 452516 = 464,86 €) no se reclaman. El TOTAL GLOBAL incluye el termo como importe documentado aunque no se reclame fiscalmente.
